{
  "modified": "2024-10-24T01:01:58Z",
  "published": "2024-06-25T13:33:10Z",
  "schema_version": "1.5.0",
  "id": "MAL-2024-4862",
  "aliases": [
    "SNYK-PYTHON-CAPMONSTERCLOUDCLIENTT-6513712"
  ],
  "summary": "Malicious code in capmonstercloudclientt (PyPI)",
  "details": "\n---\n_-= Per source details. Do not edit below this line.=-_\n",
  "affected": [
    {
      "package": {
        "ecosystem": "PyPI",
        "name": "capmonstercloudclientt",
        "purl": "pkg:pypi/capmonstercloudclientt"
      },
      "versions": [
        "1.0.0"
      ]
    }
  ],
  "references": [
    {
      "type": "ADVISORY",
      "url": "https://security.snyk.io/vuln/SNYK-PYTHON-CAPMONSTERCLOUDCLIENTT-6513712"
    },
    {
      "type": "ARTICLE",
      "url": "https://medium.com/checkmarx-security/pypi-is-under-attack-project-creation-and-user-registration-suspended-heres-the-details-c3b6291d4579"
    }
  ],
  "credits": [
    {
      "name": "ReversingLabs",
      "type": "FINDER",
      "contact": [
        "https://www.reversinglabs.com"
      ]
    }
  ],
  "database_specific": {
    "malicious-packages-origins": [
      {
        "source": "reversing-labs",
        "sha256": "5b5bd9640e1f9188980937c284f3624d0d86d88d679aa7cbead6451aaeada433",
        "import_time": "2024-06-28T02:48:26.812030734Z",
        "id": "RLMA-2024-03642",
        "modified_time": "2024-06-25T13:33:10Z",
        "versions": [
          "1.0.0"
        ]
      },
      {
        "source": "reversing-labs",
        "sha256": "a4d5821f728fc567883c8d1f95309814057a8606b1d60e30a354b6919ad01bed",
        "import_time": "2024-10-24T00:58:52.955909175Z",
        "id": "RLUA-2024-07930",
        "modified_time": "2024-10-16T14:37:33Z"
      }
    ]
  }
}
