{
  "modified": "2024-10-24T01:01:59Z",
  "published": "2024-06-25T13:39:03Z",
  "schema_version": "1.5.0",
  "id": "MAL-2024-5591",
  "aliases": [
    "SNYK-PYTHON-PYCOD-6513319"
  ],
  "summary": "Malicious code in py-cod (PyPI)",
  "details": "\n---\n_-= Per source details. Do not edit below this line.=-_\n",
  "affected": [
    {
      "package": {
        "ecosystem": "PyPI",
        "name": "py-cod",
        "purl": "pkg:pypi/py-cod"
      },
      "versions": [
        "1.0.0"
      ]
    }
  ],
  "references": [
    {
      "type": "ADVISORY",
      "url": "https://security.snyk.io/vuln/SNYK-PYTHON-PYCOD-6513319"
    },
    {
      "type": "ARTICLE",
      "url": "https://medium.com/checkmarx-security/pypi-is-under-attack-project-creation-and-user-registration-suspended-heres-the-details-c3b6291d4579"
    }
  ],
  "credits": [
    {
      "name": "ReversingLabs",
      "type": "FINDER",
      "contact": [
        "https://www.reversinglabs.com"
      ]
    }
  ],
  "database_specific": {
    "malicious-packages-origins": [
      {
        "source": "reversing-labs",
        "sha256": "3cbf69d3158d13c6dec19bf44c363d1cf6acca0481b905158ffbe6b9cc7456a5",
        "import_time": "2024-06-28T02:49:52.671661335Z",
        "id": "RLMA-2024-04373",
        "modified_time": "2024-06-25T13:39:03Z",
        "versions": [
          "1.0.0"
        ]
      },
      {
        "source": "reversing-labs",
        "sha256": "aeca3f9625c201c674d4711cbfcd3ea1873ddeee43f7eca21245e4293aa94b6e",
        "import_time": "2024-10-24T00:59:42.893651616Z",
        "id": "RLUA-2024-08806",
        "modified_time": "2024-10-16T14:46:39Z"
      }
    ]
  }
}
