{
  "modified": "2024-10-24T01:01:58Z",
  "published": "2024-06-25T13:33:19Z",
  "schema_version": "1.5.0",
  "id": "MAL-2024-4881",
  "aliases": [
    "SNYK-PYTHON-CAPMOSTERCLOUDCLINET-6513705"
  ],
  "summary": "Malicious code in capmostercloudclinet (PyPI)",
  "details": "\n---\n_-= Per source details. Do not edit below this line.=-_\n",
  "affected": [
    {
      "package": {
        "ecosystem": "PyPI",
        "name": "capmostercloudclinet",
        "purl": "pkg:pypi/capmostercloudclinet"
      },
      "versions": [
        "1.0.0"
      ]
    }
  ],
  "references": [
    {
      "type": "ADVISORY",
      "url": "https://security.snyk.io/vuln/SNYK-PYTHON-CAPMOSTERCLOUDCLINET-6513705"
    },
    {
      "type": "ARTICLE",
      "url": "https://medium.com/checkmarx-security/pypi-is-under-attack-project-creation-and-user-registration-suspended-heres-the-details-c3b6291d4579"
    }
  ],
  "credits": [
    {
      "name": "ReversingLabs",
      "type": "FINDER",
      "contact": [
        "https://www.reversinglabs.com"
      ]
    }
  ],
  "database_specific": {
    "malicious-packages-origins": [
      {
        "source": "reversing-labs",
        "sha256": "b387a7cbab5c6b262d6ee1b5be781298ab28f2df25f61a8ad075bcd61c825be5",
        "import_time": "2024-06-28T02:48:28.865176208Z",
        "id": "RLMA-2024-03661",
        "modified_time": "2024-06-25T13:33:19Z",
        "versions": [
          "1.0.0"
        ]
      },
      {
        "source": "reversing-labs",
        "sha256": "8c1a3642489006a0ea20a0f480433a6e2bf8add6dcbcbf86dc0b572d56cdee8b",
        "import_time": "2024-10-24T00:58:54.144651834Z",
        "id": "RLUA-2024-07949",
        "modified_time": "2024-10-16T14:37:45Z"
      }
    ]
  }
}
