{
  "modified": "2024-10-24T01:01:59Z",
  "published": "2024-06-25T13:42:20Z",
  "schema_version": "1.5.0",
  "id": "MAL-2024-5979",
  "aliases": [
    "SNYK-PYTHON-SELEMNIUM-6513580"
  ],
  "summary": "Malicious code in selemnium (PyPI)",
  "details": "\n---\n_-= Per source details. Do not edit below this line.=-_\n",
  "affected": [
    {
      "package": {
        "ecosystem": "PyPI",
        "name": "selemnium",
        "purl": "pkg:pypi/selemnium"
      },
      "versions": [
        "1.0.0"
      ]
    }
  ],
  "references": [
    {
      "type": "ADVISORY",
      "url": "https://security.snyk.io/vuln/SNYK-PYTHON-SELEMNIUM-6513580"
    },
    {
      "type": "ARTICLE",
      "url": "https://medium.com/checkmarx-security/pypi-is-under-attack-project-creation-and-user-registration-suspended-heres-the-details-c3b6291d4579"
    }
  ],
  "credits": [
    {
      "name": "ReversingLabs",
      "type": "FINDER",
      "contact": [
        "https://www.reversinglabs.com"
      ]
    }
  ],
  "database_specific": {
    "malicious-packages-origins": [
      {
        "source": "reversing-labs",
        "sha256": "13ba66d8db06bf31916b519952f7e34273363c0fb68c2eac7f7e4a74b79ffa39",
        "import_time": "2024-06-28T02:50:41.325370432Z",
        "id": "RLMA-2024-04780",
        "modified_time": "2024-06-25T13:42:20Z",
        "versions": [
          "1.0.0"
        ]
      },
      {
        "source": "reversing-labs",
        "sha256": "3b4a8fa099550f0ae4e35f5bdb64e39441e56ca5e92ba193bac3c9a8f209fcb5",
        "import_time": "2024-10-24T01:00:09.698034538Z",
        "id": "RLUA-2024-09244",
        "modified_time": "2024-10-16T14:51:07Z"
      }
    ]
  }
}
