{
  "modified": "2024-10-24T01:01:58Z",
  "published": "2024-06-25T13:38:05Z",
  "schema_version": "1.5.0",
  "id": "MAL-2024-5470",
  "aliases": [
    "SNYK-PYTHON-PILLIW-6513507"
  ],
  "summary": "Malicious code in pilliw (PyPI)",
  "details": "\n---\n_-= Per source details. Do not edit below this line.=-_\n",
  "affected": [
    {
      "package": {
        "ecosystem": "PyPI",
        "name": "pilliw",
        "purl": "pkg:pypi/pilliw"
      },
      "versions": [
        "1.0.0"
      ]
    }
  ],
  "references": [
    {
      "type": "ADVISORY",
      "url": "https://security.snyk.io/vuln/SNYK-PYTHON-PILLIW-6513507"
    },
    {
      "type": "ARTICLE",
      "url": "https://medium.com/checkmarx-security/pypi-is-under-attack-project-creation-and-user-registration-suspended-heres-the-details-c3b6291d4579"
    }
  ],
  "credits": [
    {
      "name": "ReversingLabs",
      "type": "FINDER",
      "contact": [
        "https://www.reversinglabs.com"
      ]
    }
  ],
  "database_specific": {
    "malicious-packages-origins": [
      {
        "source": "reversing-labs",
        "sha256": "fc8ce02cd1724ebaa1986e204666d9860e1bc308acb5fb47f5d9feed3d1e420b",
        "import_time": "2024-06-28T02:49:38.183310612Z",
        "id": "RLMA-2024-04252",
        "modified_time": "2024-06-25T13:38:05Z",
        "versions": [
          "1.0.0"
        ]
      },
      {
        "source": "reversing-labs",
        "sha256": "a44c92c42c3c2e7c60839e650ffedb1298c89ee6213c7b3c307e2e0153ba6423",
        "import_time": "2024-10-24T00:59:34.840695332Z",
        "id": "RLUA-2024-08680",
        "modified_time": "2024-10-16T14:45:23Z"
      }
    ]
  }
}
